

## 四、错误处理

### 4.1 500 错误

如果代码运行过程中发生错误，我们需要把错误信息返回给用户。HTTP 协定约定这时要返回500状态码。Koa 提供了`ctx.throw()`方法，用来抛出错误，`ctx.throw(500)`就是抛出500错误。请看下面的例子（完整代码看[这里](https://github.com/ruanyf/koa-demos/blob/master/demos/14.js)）。

> ```javascript
> // demos/14.js
> const main = ctx => {
> ctx.throw(500);
> };
> ```

运行这个 demo。

> ```bash
> $ node demos/14.js
> ```

访问 http://127.0.0.1:3000，你会看到一个500错误页"Internal Server Error"。

![img](http://www.ruanyifeng.com/blogimg/asset/2017/bg2017080807.png)

### 4.2 404错误

如果将`ctx.response.status`设置成404，就相当于`ctx.throw(404)`，返回404错误。请看下面的例子（完整代码看[这里](https://github.com/ruanyf/koa-demos/blob/master/demos/15.js)）。

> ```javascript
> // demos/15.js
> const main = ctx => {
> ctx.response.status = 404;
> ctx.response.body = 'Page Not Found';
> };
> ```

运行这个 demo。

> ```bash
> $ node demos/15.js
> ```

访问 http://127.0.0.1:3000 ，你就看到一个404页面"Page Not Found"。

![img](http://www.ruanyifeng.com/blogimg/asset/2017/bg2017080808.png)

### 4.3 处理错误的中间件

为了方便处理错误，最好使用`try...catch`将其捕获。但是，为每个中间件都写`try...catch`太麻烦，我们可以让最外层的中间件，负责所有中间件的错误处理。请看下面的例子（完整代码看[这里](https://github.com/ruanyf/koa-demos/blob/master/demos/16.js)）。

> ```javascript
> // demos/16.js
> const handler = async (ctx, next) => {
> try {
>  await next();
> } catch (err) {
>  ctx.response.status = err.statusCode || err.status || 500;
>  ctx.response.body = {
>    message: err.message
>  };
> }
> };
> 
> const main = ctx => {
> ctx.throw(500);
> };
> 
> app.use(handler);
> app.use(main);
> ```

运行这个 demo。

> ```bash
> $ node demos/16.js
> ```

访问 http://127.0.0.1:3000 ，你会看到一个500页，里面有报错提示 `{"message":"Internal Server Error"}`。

![img](http://www.ruanyifeng.com/blogimg/asset/2017/bg2017080809.png)

### 4.4 error 事件的监听

运行过程中一旦出错，Koa 会触发一个`error`事件。监听这个事件，也可以处理错误。请看下面的例子（完整代码看[这里](https://github.com/ruanyf/koa-demos/blob/master/demos/17.js)）。

> ```javascript
> // demos/17.js
> const main = ctx => {
> ctx.throw(500);
> };
> 
> app.on('error', (err, ctx) =>
> console.error('server error', err);
> );
> ```

运行这个 demo。

> ```bash
> $ node demos/17.js
> ```

访问 http://127.0.0.1:3000 ，你会在命令行窗口看到"server error xxx"。

### 4.5 释放 error 事件

需要注意的是，如果错误被`try...catch`捕获，就不会触发`error`事件。这时，必须调用`ctx.app.emit()`，手动释放`error`事件，才能让监听函数生效。请看下面的例子（完整代码看[这里](https://github.com/ruanyf/koa-demos/blob/master/demos/18.js)）。

> ```javascript
> // demos/18.js`
> const handler = async (ctx, next) => {
> try {
>  await next();
> } catch (err) {
>  ctx.response.status = err.statusCode || err.status || 500;
>  ctx.response.type = 'html';
>  ctx.response.body = '<p>Something wrong, please contact administrator.</p>';
>  ctx.app.emit('error', err, ctx);
> }
> };
> 
> const main = ctx => {
> ctx.throw(500);
> };
> 
> app.on('error', function(err) {
> console.log('logging error ', err.message);
> console.log(err);
> });
> ```

上面代码中，`main`函数抛出错误，被`handler`函数捕获。`catch`代码块里面使用`ctx.app.emit()`手动释放`error`事件，才能让监听函数监听到。

运行这个 demo。

> ```bash
> $ node demos/18.js
> ```

访问 http://127.0.0.1:3000 ，你会在命令行窗口看到`logging error`。